# WebSocket "Bad Response from Server" Hatası - Detaylı Analiz

## 🔍 Hata Özeti

**Client Error**: `WebSocket receive error: There was a bad response from the server.`  
**Backend Error**: `send_error failed: Expected ASGI message "websocket.accept", "websocket.close" or "websocket.http.response.start", but got 'websocket.send'`  
**ASGI Error**: `ASGI callable returned without sending handshake.`

## 🎯 Sorunun Kökeni

### ASGI WebSocket Protocol İhlali

ASGI WebSocket protocol'ü şu sırayı zorunlu kılar:
1. **websocket.accept** - Handshake tamamla
2. **websocket.send** - Mesaj gönder (sadece accept sonrası)
3. **websocket.close** - Bağlantıyı kapat

Backend, **handshake accept etmeden mesaj göndermeye çalışıyor**.

## 📋 Kodda Hata Analizi

### 1. ws.py - WebSocket Ingest Endpoint

```python
@router.websocket("/ws/ingest/meetings/{meeting_id}")
async def websocket_ingest(websocket: WebSocket, meeting_id: str, token: str = Query(...)):
    try:
        # 🔴 PROBLEM: Auth failure sonrası accept yapmadan close çalışıyor
        try:
            claims = decode_jwt_token(token)
            logger.info(f"Ingest auth: {claims.email}")
        except SecurityError as e:
            await websocket.close(code=4001, reason=f"auth failed: {e}")  # ❌ Accept etmeden close!
            return

        # ✅ Connect başarılı ise accept yapılıyor
        if not await ws_manager.connect_ingest(websocket, meeting_id):
            return
            
        # 🔴 PROBLEM: Handshake exception'da accept sonrası send yapılıyor ama return ediliyor
        try:
            hs_data = await asyncio.wait_for(websocket.receive_text(), timeout=10.0)
            hs = IngestHandshakeMessage.model_validate_json(hs_data)
            logger.info(f"Handshake: {hs}")
        except Exception as e:
            await websocket.send_text(json.dumps({"status": "error", "message": f"Handshake invalid: {e}"}))  # ✅ Accept yapılmış ama...
            return  # ❌ Connection açık kalıyor!

        # 🔴 PROBLEM: Validation error'larında da aynı sorun
        if hs.sample_rate != settings.INGEST_SAMPLE_RATE:
            await websocket.send_text(json.dumps({"status": "error", "message": f"Invalid sample rate {hs.sample_rate}"}))  # ✅ Accept yapılmış ama...
            return  # ❌ Connection açık kalıyor!
```

### 2. connection.py - WebSocket Manager

```python
class ConnectionManager:
    async def connect_ingest(self, websocket: WebSocket, meeting_id: str) -> bool:
        if meeting_id in self.ingest_connections:
            await self._send_error(websocket, "ingest_exists", "Ingest already active")  # 🔴 Accept etmeden send!
            return False
            
        await websocket.accept()  # ✅ Normal flow'da accept yapılıyor
        # ...

    async def _send_error(self, websocket: WebSocket, code: str, message: str):
        payload = {"type": "error", "code": code, "message": message}
        try:
            await websocket.send_text(json.dumps(payload))  # 🔴 Accept kontrolü yok!
        except Exception as e:
            logger.error(f"send_error failed: {e}")  # ❌ Bu hata mesajı burada oluşuyor!
```

### 3. MacClient - BackendIngestWS.swift

```swift
// Client tarafında doğru implementation var
func open(baseURL: String, meetingId: String, jwtToken: String, handshake: Handshake) {
    // WebSocket connection açıyor
    let task = session.webSocketTask(with: url)
    task.resume()
    
    // Handshake gönderiyor (TEXT frame)
    let data = try JSONEncoder().encode(handshake)
    let txt = String(data: data, encoding: .utf8) ?? "{\"type\":\"handshake\"}"
    sendText(txt)  // ✅ Client tarafı doğru
}
```

## 🚨 Kritik Sorunlar

### 1. Auth Failure'da ASGI Protocol İhlali
```python
# ❌ Yanlış:
except SecurityError as e:
    await websocket.close(code=4001, reason=f"auth failed: {e}")  # Accept etmeden close!
    return

# ✅ Doğru:
except SecurityError as e:
    await websocket.accept()  # Önce accept
    await websocket.close(code=4001, reason=f"auth failed: {e}")  # Sonra close
    return
```

### 2. Error Handler'da Accept Kontrolü Yok
```python
# ❌ Yanlış:
async def _send_error(self, websocket: WebSocket, code: str, message: str):
    await websocket.send_text(json.dumps(payload))  # Accept edilmiş mi kontrol yok!

# ✅ Doğru:
async def _send_error(self, websocket: WebSocket, code: str, message: str):
    try:
        await websocket.accept()  # Eğer henüz accept edilmemişse
    except RuntimeError:  # Zaten accept edilmişse
        pass
    await websocket.send_text(json.dumps(payload))
    await websocket.close()
```

### 3. Exception Sonrası Connection Cleanup Eksik
```python
# ❌ Yanlış:
except Exception as e:
    await websocket.send_text(json.dumps({"status": "error"}))
    return  # Connection açık kalıyor!

# ✅ Doğru:
except Exception as e:
    await websocket.send_text(json.dumps({"status": "error"}))
    await websocket.close()  # Connection'ı kapat
    return
```

## 🔧 Çözüm Planı

### 1. Auth Error Handling Düzeltmesi
```python
@router.websocket("/ws/ingest/meetings/{meeting_id}")
async def websocket_ingest(websocket: WebSocket, meeting_id: str, token: str = Query(...)):
    try:
        # Auth önce accept, sonra validate
        await websocket.accept()  # ✅ Her durumda önce accept
        
        try:
            claims = decode_jwt_token(token)
            logger.info(f"Ingest auth: {claims.email}")
        except SecurityError as e:
            await websocket.close(code=4001, reason=f"auth failed: {e}")
            return
        # ... rest of code
```

### 2. Connection Manager Error Handling
```python
async def connect_ingest(self, websocket: WebSocket, meeting_id: str) -> bool:
    # Önce accept, sonra validate
    await websocket.accept()
    
    if meeting_id in self.ingest_connections:
        await websocket.close(code=4002, reason="Ingest already active")
        return False
    # ... rest of code
```

### 3. Safe Error Sender
```python
async def _send_error_and_close(self, websocket: WebSocket, code: str, message: str):
    """Send error and properly close connection."""
    payload = {"type": "error", "code": code, "message": message}
    try:
        await websocket.send_text(json.dumps(payload))
        await websocket.close(code=4000, reason=message)
    except Exception as e:
        logger.error(f"send_error_and_close failed: {e}")
        try:
            await websocket.close()
        except:
            pass
```

### 4. Exception Safety Wrapper
```python
async def safe_websocket_operation(websocket: WebSocket, operation):
    """Wrapper for safe WebSocket operations."""
    try:
        await operation()
    except Exception as e:
        logger.error(f"WebSocket operation failed: {e}")
        try:
            if websocket.client_state == WebSocketState.CONNECTED:
                await websocket.close(code=4000, reason="Internal error")
        except:
            pass
```

## 📊 Implementation Roadmap

### Phase 1: Critical Fixes
1. **ws.py**: Auth error handling - accept before close
2. **connection.py**: Safe error sending with proper accept/close flow
3. **ws.py**: Exception cleanup - close connections on errors

### Phase 2: Robust Error Handling
1. **WebSocket state checking** before send operations
2. **Graceful degradation** when connections fail
3. **Connection pooling** improvements

### Phase 3: Testing & Validation
1. **Unit tests** for WebSocket edge cases
2. **Integration tests** with MacClient
3. **Load testing** for concurrent connections

## 🎯 Expected Results

Bu düzeltmeler sonrası:
- ✅ ASGI protocol violations çözülecek
- ✅ "Bad response from server" hatası kaybolacak  
- ✅ WebSocket connections stabil çalışacak
- ✅ Error handling robust hale gelecek
- ✅ MacClient - Backend seamless integration

**Root Cause**: ASGI WebSocket protocol'ünün **accept → send → close** sırasına uyulmaması  
**Solution**: Error handling flow'unda proper accept/close sequence implementation
